[2022-07-29 04:40:40,968]^;INFO^;224^;_internal.py^;_log()^; * Running on http://127.0.0.1:5000 (Press CTRL+C to quit)
[2022-07-29 04:40:41,422]^;INFO^;111^;app.py^;predict()^;predict called 
[2022-07-29 04:40:41,468]^;INFO^;224^;_internal.py^;_log()^;127.0.0.1 - - [29/Jul/2022 04:40:41] "GET /predict HTTP/1.1" 200 -
[2022-07-29 04:40:41,729]^;INFO^;224^;_internal.py^;_log()^;127.0.0.1 - - [29/Jul/2022 04:40:41] "[36mGET /static/styles.css HTTP/1.1[0m" 304 -
[2022-07-29 04:40:41,773]^;INFO^;224^;_internal.py^;_log()^;127.0.0.1 - - [29/Jul/2022 04:40:41] "[36mGET /static/logoimage.png HTTP/1.1[0m" 304 -
[2022-07-29 04:40:42,216]^;INFO^;224^;_internal.py^;_log()^;127.0.0.1 - - [29/Jul/2022 04:40:42] "[36mGET /static/image.jpg HTTP/1.1[0m" 304 -
[2022-07-29 04:40:49,076]^;INFO^;111^;app.py^;predict()^;predict called 
[2022-07-29 04:40:49,078]^;INFO^;224^;_internal.py^;_log()^;127.0.0.1 - - [29/Jul/2022 04:40:49] "GET /predict HTTP/1.1" 200 -
[2022-07-29 04:40:49,140]^;INFO^;224^;_internal.py^;_log()^;127.0.0.1 - - [29/Jul/2022 04:40:49] "[36mGET /static/styles.css HTTP/1.1[0m" 304 -
[2022-07-29 04:40:49,145]^;INFO^;224^;_internal.py^;_log()^;127.0.0.1 - - [29/Jul/2022 04:40:49] "[36mGET /static/logoimage.png HTTP/1.1[0m" 304 -
[2022-07-29 04:40:54,658]^;INFO^;111^;app.py^;predict()^;predict called 
[2022-07-29 04:40:54,686]^;INFO^;224^;_internal.py^;_log()^;127.0.0.1 - - [29/Jul/2022 04:40:54] "GET /predict HTTP/1.1" 200 -
[2022-07-29 04:40:54,989]^;INFO^;224^;_internal.py^;_log()^;127.0.0.1 - - [29/Jul/2022 04:40:54] "[36mGET /static/styles.css HTTP/1.1[0m" 304 -
[2022-07-29 04:40:55,061]^;INFO^;224^;_internal.py^;_log()^;127.0.0.1 - - [29/Jul/2022 04:40:55] "[36mGET /static/logoimage.png HTTP/1.1[0m" 304 -
[2022-07-29 04:41:06,831]^;INFO^;111^;app.py^;predict()^;predict called 
[2022-07-29 04:41:06,863]^;INFO^;143^;app.py^;predict()^;prediction_data: <mlstoresales.entity.predictor.Prediction_Data object at 0x000001EE0572E320>
[2022-07-29 04:41:07,143]^;INFO^;164^;app.py^;predict()^;app_predictor: <mlstoresales.entity.predictor.App_predictor object at 0x000001EE0572E9E8>
[2022-07-29 04:41:07,172]^;ERROR^;1456^;app.py^;log_exception()^;Exception on /predict [POST]
Traceback (most recent call last):
  File "C:\fullstackdatascience\ineuron project\ML_StoreSales\mlstoresales\util\util.py", line 85, in load_object
    return dill.load(file_obj)
  File "C:\fullstackdatascience\ineuron project\ML_StoreSales\venv\lib\site-packages\dill\_dill.py", line 373, in load
    return Unpickler(file, ignore=ignore, **kwds).load()
  File "C:\fullstackdatascience\ineuron project\ML_StoreSales\venv\lib\site-packages\dill\_dill.py", line 646, in load
    obj = StockUnpickler.load(self)
  File "C:\fullstackdatascience\ineuron project\ML_StoreSales\venv\lib\site-packages\dill\_dill.py", line 636, in find_class
    return StockUnpickler.find_class(self, module, name)
ModuleNotFoundError: No module named 'BigmartsalesPrediction'

The above exception was the direct cause of the following exception:

Traceback (most recent call last):
  File "C:\fullstackdatascience\ineuron project\ML_StoreSales\mlstoresales\entity\predictor.py", line 92, in predict
    model = load_object(file_path=model_path)
  File "C:\fullstackdatascience\ineuron project\ML_StoreSales\mlstoresales\util\util.py", line 87, in load_object
    raise HousingException(e,sys) from e
mlstoresales.exception.HousingException: Error occured in script: [C:\fullstackdatascience\ineuron project\ML_StoreSales\mlstoresales\util\util.py] at line number: [87] error message: [No module named 'BigmartsalesPrediction']

The above exception was the direct cause of the following exception:

Traceback (most recent call last):
  File "app.py", line 165, in predict
    Item_Outlet_Sales= app_predictor.predict(X=prediction_df)
  File "C:\fullstackdatascience\ineuron project\ML_StoreSales\mlstoresales\entity\predictor.py", line 98, in predict
    raise HousingException(e, sys) from e
mlstoresales.exception.HousingException: Error occured in script: [C:\fullstackdatascience\ineuron project\ML_StoreSales\mlstoresales\entity\predictor.py] at line number: [98] error message: [Error occured in script: [C:\fullstackdatascience\ineuron project\ML_StoreSales\mlstoresales\util\util.py] at line number: [87] error message: [No module named 'BigmartsalesPrediction']]

During handling of the above exception, another exception occurred:

Traceback (most recent call last):
  File "C:\fullstackdatascience\ineuron project\ML_StoreSales\venv\lib\site-packages\flask\app.py", line 2077, in wsgi_app
    response = self.full_dispatch_request()
  File "C:\fullstackdatascience\ineuron project\ML_StoreSales\venv\lib\site-packages\flask\app.py", line 1525, in full_dispatch_request
    rv = self.handle_user_exception(e)
  File "C:\fullstackdatascience\ineuron project\ML_StoreSales\venv\lib\site-packages\flask\app.py", line 1523, in full_dispatch_request
    rv = self.dispatch_request()
  File "C:\fullstackdatascience\ineuron project\ML_StoreSales\venv\lib\site-packages\flask\app.py", line 1509, in dispatch_request
    return self.ensure_sync(self.view_functions[rule.endpoint])(**req.view_args)
  File "app.py", line 175, in predict
    raise HousingException(e , sys)
mlstoresales.exception.HousingException: Error occured in script: [app.py] at line number: [175] error message: [Error occured in script: [C:\fullstackdatascience\ineuron project\ML_StoreSales\mlstoresales\entity\predictor.py] at line number: [98] error message: [Error occured in script: [C:\fullstackdatascience\ineuron project\ML_StoreSales\mlstoresales\util\util.py] at line number: [87] error message: [No module named 'BigmartsalesPrediction']]]
[2022-07-29 04:41:07,211]^;INFO^;224^;_internal.py^;_log()^;127.0.0.1 - - [29/Jul/2022 04:41:07] "[35m[1mPOST /predict HTTP/1.1[0m" 500 -
