[2022-07-27 06:27:01,902]^;INFO^;224^;_internal.py^;_log()^; * Running on http://127.0.0.1:5000 (Press CTRL+C to quit)
[2022-07-27 06:27:25,306]^;INFO^;110^;app.py^;predict()^;predict called 
[2022-07-27 06:27:25,329]^;INFO^;142^;app.py^;predict()^;prediction_data: <mlstoresales.entity.predictor.Prediction_Data object at 0x000002BB7171D780>
[2022-07-27 06:27:25,388]^;INFO^;146^;app.py^;predict()^;app_predictor: <mlstoresales.entity.predictor.App_predictor object at 0x000002BB71768438>
[2022-07-27 06:27:25,401]^;ERROR^;1456^;app.py^;log_exception()^;Exception on /predict [POST]
Traceback (most recent call last):
  File "C:\fullstackdatascience\ineuron project\ML_StoreSales\mlstoresales\util\util.py", line 85, in load_object
    return dill.load(file_obj)
  File "C:\fullstackdatascience\ineuron project\ML_StoreSales\venv\lib\site-packages\dill\_dill.py", line 373, in load
    return Unpickler(file, ignore=ignore, **kwds).load()
  File "C:\fullstackdatascience\ineuron project\ML_StoreSales\venv\lib\site-packages\dill\_dill.py", line 646, in load
    obj = StockUnpickler.load(self)
  File "C:\fullstackdatascience\ineuron project\ML_StoreSales\venv\lib\site-packages\dill\_dill.py", line 636, in find_class
    return StockUnpickler.find_class(self, module, name)
ModuleNotFoundError: No module named 'BigmartsalesPrediction'

The above exception was the direct cause of the following exception:

Traceback (most recent call last):
  File "C:\fullstackdatascience\ineuron project\ML_StoreSales\mlstoresales\entity\predictor.py", line 92, in predict
    model = load_object(file_path=model_path)
  File "C:\fullstackdatascience\ineuron project\ML_StoreSales\mlstoresales\util\util.py", line 87, in load_object
    raise HousingException(e,sys) from e
mlstoresales.exception.HousingException: Error occured in script: [C:\fullstackdatascience\ineuron project\ML_StoreSales\mlstoresales\util\util.py] at line number: [87] error message: [No module named 'BigmartsalesPrediction']

The above exception was the direct cause of the following exception:

Traceback (most recent call last):
  File "app.py", line 147, in predict
    Item_Outlet_Sales= app_predictor.predict(X=prediction_df)
  File "C:\fullstackdatascience\ineuron project\ML_StoreSales\mlstoresales\entity\predictor.py", line 96, in predict
    raise HousingException(e, sys) from e
mlstoresales.exception.HousingException: Error occured in script: [C:\fullstackdatascience\ineuron project\ML_StoreSales\mlstoresales\entity\predictor.py] at line number: [96] error message: [Error occured in script: [C:\fullstackdatascience\ineuron project\ML_StoreSales\mlstoresales\util\util.py] at line number: [87] error message: [No module named 'BigmartsalesPrediction']]

During handling of the above exception, another exception occurred:

Traceback (most recent call last):
  File "C:\fullstackdatascience\ineuron project\ML_StoreSales\venv\lib\site-packages\flask\app.py", line 2077, in wsgi_app
    response = self.full_dispatch_request()
  File "C:\fullstackdatascience\ineuron project\ML_StoreSales\venv\lib\site-packages\flask\app.py", line 1525, in full_dispatch_request
    rv = self.handle_user_exception(e)
  File "C:\fullstackdatascience\ineuron project\ML_StoreSales\venv\lib\site-packages\flask\app.py", line 1523, in full_dispatch_request
    rv = self.dispatch_request()
  File "C:\fullstackdatascience\ineuron project\ML_StoreSales\venv\lib\site-packages\flask\app.py", line 1509, in dispatch_request
    return self.ensure_sync(self.view_functions[rule.endpoint])(**req.view_args)
  File "app.py", line 154, in predict
    raise HousingException(e , sys)
mlstoresales.exception.HousingException: Error occured in script: [app.py] at line number: [154] error message: [Error occured in script: [C:\fullstackdatascience\ineuron project\ML_StoreSales\mlstoresales\entity\predictor.py] at line number: [96] error message: [Error occured in script: [C:\fullstackdatascience\ineuron project\ML_StoreSales\mlstoresales\util\util.py] at line number: [87] error message: [No module named 'BigmartsalesPrediction']]]
[2022-07-27 06:27:25,430]^;INFO^;224^;_internal.py^;_log()^;127.0.0.1 - - [27/Jul/2022 06:27:25] "[35m[1mPOST /predict HTTP/1.1[0m" 500 -
[2022-07-27 06:27:54,102]^;INFO^;110^;app.py^;predict()^;predict called 
[2022-07-27 06:27:54,696]^;INFO^;224^;_internal.py^;_log()^;127.0.0.1 - - [27/Jul/2022 06:27:54] "GET /predict HTTP/1.1" 200 -
[2022-07-27 06:27:55,260]^;INFO^;224^;_internal.py^;_log()^;127.0.0.1 - - [27/Jul/2022 06:27:55] "[36mGET /static/logoimage.png HTTP/1.1[0m" 304 -
[2022-07-27 06:28:13,530]^;INFO^;110^;app.py^;predict()^;predict called 
[2022-07-27 06:28:13,563]^;INFO^;142^;app.py^;predict()^;prediction_data: <mlstoresales.entity.predictor.Prediction_Data object at 0x000002BB7173BDD8>
[2022-07-27 06:28:13,642]^;INFO^;146^;app.py^;predict()^;app_predictor: <mlstoresales.entity.predictor.App_predictor object at 0x000002BB71768048>
[2022-07-27 06:28:13,662]^;ERROR^;1456^;app.py^;log_exception()^;Exception on /predict [POST]
Traceback (most recent call last):
  File "C:\fullstackdatascience\ineuron project\ML_StoreSales\mlstoresales\util\util.py", line 85, in load_object
    return dill.load(file_obj)
  File "C:\fullstackdatascience\ineuron project\ML_StoreSales\venv\lib\site-packages\dill\_dill.py", line 373, in load
    return Unpickler(file, ignore=ignore, **kwds).load()
  File "C:\fullstackdatascience\ineuron project\ML_StoreSales\venv\lib\site-packages\dill\_dill.py", line 646, in load
    obj = StockUnpickler.load(self)
  File "C:\fullstackdatascience\ineuron project\ML_StoreSales\venv\lib\site-packages\dill\_dill.py", line 636, in find_class
    return StockUnpickler.find_class(self, module, name)
ModuleNotFoundError: No module named 'BigmartsalesPrediction'

The above exception was the direct cause of the following exception:

Traceback (most recent call last):
  File "C:\fullstackdatascience\ineuron project\ML_StoreSales\mlstoresales\entity\predictor.py", line 92, in predict
    model = load_object(file_path=model_path)
  File "C:\fullstackdatascience\ineuron project\ML_StoreSales\mlstoresales\util\util.py", line 87, in load_object
    raise HousingException(e,sys) from e
mlstoresales.exception.HousingException: Error occured in script: [C:\fullstackdatascience\ineuron project\ML_StoreSales\mlstoresales\util\util.py] at line number: [87] error message: [No module named 'BigmartsalesPrediction']

The above exception was the direct cause of the following exception:

Traceback (most recent call last):
  File "app.py", line 147, in predict
    Item_Outlet_Sales= app_predictor.predict(X=prediction_df)
  File "C:\fullstackdatascience\ineuron project\ML_StoreSales\mlstoresales\entity\predictor.py", line 96, in predict
    raise HousingException(e, sys) from e
mlstoresales.exception.HousingException: Error occured in script: [C:\fullstackdatascience\ineuron project\ML_StoreSales\mlstoresales\entity\predictor.py] at line number: [96] error message: [Error occured in script: [C:\fullstackdatascience\ineuron project\ML_StoreSales\mlstoresales\util\util.py] at line number: [87] error message: [No module named 'BigmartsalesPrediction']]

During handling of the above exception, another exception occurred:

Traceback (most recent call last):
  File "C:\fullstackdatascience\ineuron project\ML_StoreSales\venv\lib\site-packages\flask\app.py", line 2077, in wsgi_app
    response = self.full_dispatch_request()
  File "C:\fullstackdatascience\ineuron project\ML_StoreSales\venv\lib\site-packages\flask\app.py", line 1525, in full_dispatch_request
    rv = self.handle_user_exception(e)
  File "C:\fullstackdatascience\ineuron project\ML_StoreSales\venv\lib\site-packages\flask\app.py", line 1523, in full_dispatch_request
    rv = self.dispatch_request()
  File "C:\fullstackdatascience\ineuron project\ML_StoreSales\venv\lib\site-packages\flask\app.py", line 1509, in dispatch_request
    return self.ensure_sync(self.view_functions[rule.endpoint])(**req.view_args)
  File "app.py", line 154, in predict
    raise HousingException(e , sys)
mlstoresales.exception.HousingException: Error occured in script: [app.py] at line number: [154] error message: [Error occured in script: [C:\fullstackdatascience\ineuron project\ML_StoreSales\mlstoresales\entity\predictor.py] at line number: [96] error message: [Error occured in script: [C:\fullstackdatascience\ineuron project\ML_StoreSales\mlstoresales\util\util.py] at line number: [87] error message: [No module named 'BigmartsalesPrediction']]]
[2022-07-27 06:28:13,684]^;INFO^;224^;_internal.py^;_log()^;127.0.0.1 - - [27/Jul/2022 06:28:13] "[35m[1mPOST /predict HTTP/1.1[0m" 500 -
